---
layout: post
title: Node.js Error Handling
date: 2017-02-22 00:00:00 +0900
categories: Node js
---

Node.js는 Javascript로 개발한다. 아래 코드를 주목해보자.

```javascript
try {
    null.error;
} catch (e) {
    console.error('catch error: ', e.stack);
}
```

평상시 에러 잡는 코드를 작성할 때 사용한다. 아무런 의구심도 들지 않는다.
자연스럽게 catch에서 실행될 것이란 걸 알기 때문이다.

아이러니하게도, 비동기 방식으로 개발하게 된다면 상황은 달라진다.
순차적으로 진행되는 코드에 익숙한 게 대부분이다. 들쑥날쑥 동작하는 코드를 보는 순간 당황할 수 있다.

```javascript
'use strict';
const fs = require('fs');

try {
    fs.readFile('bad', (err) => {
        throw new Error('test error');
    });
} catch (e) {
    console.error('catch error: ', e.stack);
}
```

비동기 방식으로 파일을 읽고 있으며, 동일하게 에러를 발생시킨다.
catch로 들어오지 못하고, process exit 되는 상황에 놓이게 된다.
callback function은 try ~ catch scope에서 벗어나기 때문에 잡을 수 없다.

```javascript
const fs = require('fs');

try {
    fs.readFile('bad', (err) => {
        try {
            throw new Error('test error');
        } catch (e) {
            console.error('fs catch error: ', e.stack);
        }
    });
} catch (e) {
    console.error('catch error: ', e.stack);
}
```

사용하던 대로, 벗어나고 있는 scope에 새로운 try ~ catch를 사용하면 생각대로 진행된다.
전적으로 의존한다면, try ~ catch 천국이 될 것이다.
좀 더 나은 방법으로 고민해보면, node.js의 domain module을 사용하면 된다.
현재도 Deprecated로 명시가 되어있으나, 마땅한 대안이 없어 유지되고 있는 것으로 보인다.

쉽게 보면, global scope, local scope 2가지가 전부다.

```
const fs = require('fs');
const domain = require('domain');

const fsProtect = domain.create();

fsProtect.on('error', (err) => {
    console.log(err);
    console.error('domain error: ', err.stack);
});

fsProtect.run(() => {
    fs.readFile('bad', (err) => {
        throw new Error('test error');
    });
});
```

run 함수는, try ~ catch scope와 동일하게 보면 이해가 쉽게 된다.
callback function의 영역도 scope에 포함 되기 때문에, error 이벤트로 진입하게 된다.

```
{ Error: test error
    at ReadFileContext.fs.readFile [as callback] (error.js:14:15)
    at FSReqWrap.readFileAfterOpen [as oncomplete] (fs.js:365:13)
  domain:
   Domain {
     domain: null,
     _events: { error: [Function] },
     _eventsCount: 1,
     _maxListeners: undefined,
     members: [] },
  domainThrown: true }
```

error 객체를 자세히 살펴보면, 다른 점이 한가지 있다. run 함수 scope 안에서 에러가 발생하는 경우,
domain 객체가 바인딩 되며, _events에 error 이벤트가 등록되어 있다. 이 점 때문에 error 이벤트를 사전에 등록해줘야만 한다.

간편하게 사용할 수 있는 대표적인 방법이며, 대부분 위와 같은 방식을 사용한다.
한가지 의구심이 드는 부분은, 원하는대로 scope 조절은 불가능 하다는 것이다.

```javascript
const fs = require('fs');
const domain = require('domain');

const fsProtect = domain.create();

fsProtect.on('error', (err) => {
    console.log(err);
    console.error('domain error: ', err.stack);
});

fs.readFile('bad', fsProtect.bind((err) => {
    throw new Error('1234');
}));
```

try ~ catch scope를 생각해보자. 벗어나는 부분만, bind 함수로 scope 영역을 확대했으며,
동일하게 error 이벤트가 등록되어 있다. scope 조절은 입맛에 맞게 할 수 있다.

주의할 점 중 한 가지는, 활성화된 domain을 명시적으로 종료해줘야 한다.
그렇지 않다면, 이 후에 실행되는 코드에서 에러가 발생하는 경우, 등록되어 있는 error 이벤트가 호출될 것이다.
상황에 따라, 애플리케이션이 멈출 수도 있고, 대응하는 시간이 길어질 수 있으니, 꼭 확인이 필요하다.
